{"@timestamp":"2022-12-27T11:04:22.329Z","log.level":"info","message":"1 A log message","ecs":{"version":"1.6.0"},"extra":"test","logger":"__main__"}
{"@timestamp":"2022-12-27T11:04:22.329Z","log.level":"error","message":"2 A key error","ecs":{"version":"1.6.0"},"logger":"all_logger.sub_module"}
{"@timestamp":"2022-12-27T11:04:22.329Z","log.level":"error","message":"3 cannot find key.","ecs":{"version":"1.6.0"},"exception":"Traceback (most recent call last):\n  File \"/home/sander/alliander/alliander-logging/all_logger/sub_module/__init__.py\", line 11, in a_raising_function\n    result = 2 * a[\"c\"]\nKeyError: 'c'","logger":"all_logger.sub_module"}
{"@timestamp":"2022-12-27T11:04:22.330Z","log.level":"warning","message":"4 Something went wrong","ecs":{"version":"1.6.0"},"exception":"Traceback (most recent call last):\n  File \"/home/sander/alliander/alliander-logging/all_logger/sub_module/__init__.py\", line 11, in a_raising_function\n    result = 2 * a[\"c\"]\nKeyError: 'c'\n\nDuring handling of the above exception, another exception occurred:\n\nTraceback (most recent call last):\n  File \"/home/sander/alliander/alliander-logging/all_logger/new_alliander_logging.py\", line 26, in <module>\n    sub_module.a_raising_function()\n  File \"/home/sander/alliander/alliander-logging/all_logger/sub_module/__init__.py\", line 14, in a_raising_function\n    raise ValueError\nValueError","logger":"__main__"}
{"@timestamp":"2022-12-27T11:04:22.330Z","log.level":"error","message":"5 this is a problem","an_argument":"this is the argument","ecs":{"version":"1.6.0"},"exception":"Traceback (most recent call last):\n  File \"/home/sander/alliander/alliander-logging/all_logger/new_alliander_logging.py\", line 31, in <module>\n    raise CustomException(\"wrong wrong\", \"this is the argument\")\nCustomException: ('wrong wrong', 'this is the argument')","logger":"__main__"}
2023-02-19T07:32:56.254753Z [error    ] 6 this 1 is a problem              [__main__] an_argument=this is the argument message=wrong wrong
2023-02-19T07:32:56.254753Z [error    ] 7 this 2 is a problem              [__main__] an_argument=this is the argument message=wrong wrong
2023-02-19T07:32:56.254753Z [warn    ] 8 this 3 is a warning              [__main__] an_argument=this is the argument message=wrong wrong
